2025-06-16 15:09:31,442 | INFO | üöÄ Logger initialized at logs\robo_logger_2025-06-16_15-09-31.log
2025-06-16 15:10:12,065 | INFO | Detected task type: CLASSIFICATION
2025-06-16 15:10:12,069 | WARNING | Not enough data for stratified train_test_split (min class count: 1). Using non-stratified split.
2025-06-16 15:10:12,069 | INFO | üîß Training Models with Hyperparameter Tuning...
2025-06-16 15:10:12,069 | INFO |   Training LogisticRegression...
2025-06-16 15:10:16,822 | INFO |   LogisticRegression - Primary Metric (Accuracy): 0.0000
2025-06-16 15:10:16,823 | INFO |   Training DecisionTree...
2025-06-16 15:10:20,397 | INFO |   DecisionTree - Primary Metric (Accuracy): 0.0000
2025-06-16 15:10:20,399 | INFO |   Training RandomForest...
2025-06-16 15:10:21,060 | INFO |   RandomForest - Primary Metric (Accuracy): 0.0000
2025-06-16 15:10:21,060 | INFO |   Training KNN...
2025-06-16 15:10:23,972 | ERROR |   Skipping KNN due to error: Expected n_neighbors <= n_samples_fit, but n_neighbors = 5, n_samples_fit = 4, n_samples = 4
joblib.externals.loky.process_executor._RemoteTraceback: 
"""
Traceback (most recent call last):
  File "E:\robo-data-scientist\venv\lib\site-packages\joblib\externals\loky\process_executor.py", line 490, in _process_worker
    r = call_item()
  File "E:\robo-data-scientist\venv\lib\site-packages\joblib\externals\loky\process_executor.py", line 291, in __call__
    return self.fn(*self.args, **self.kwargs)
  File "E:\robo-data-scientist\venv\lib\site-packages\joblib\parallel.py", line 607, in __call__
    return [func(*args, **kwargs) for func, args, kwargs in self.items]
  File "E:\robo-data-scientist\venv\lib\site-packages\joblib\parallel.py", line 607, in <listcomp>
    return [func(*args, **kwargs) for func, args, kwargs in self.items]
  File "E:\robo-data-scientist\venv\lib\site-packages\sklearn\utils\parallel.py", line 147, in __call__
    return self.function(*args, **kwargs)
  File "E:\robo-data-scientist\venv\lib\site-packages\sklearn\model_selection\_validation.py", line 881, in _fit_and_score
    test_scores = _score(
  File "E:\robo-data-scientist\venv\lib\site-packages\sklearn\model_selection\_validation.py", line 942, in _score
    scores = scorer(estimator, X_test, y_test, **score_params)
  File "E:\robo-data-scientist\venv\lib\site-packages\sklearn\metrics\_scorer.py", line 308, in __call__
    return self._score(partial(_cached_call, None), estimator, X, y_true, **_kwargs)
  File "E:\robo-data-scientist\venv\lib\site-packages\sklearn\metrics\_scorer.py", line 400, in _score
    y_pred = method_caller(
  File "E:\robo-data-scientist\venv\lib\site-packages\sklearn\metrics\_scorer.py", line 90, in _cached_call
    result, _ = _get_response_values(
  File "E:\robo-data-scientist\venv\lib\site-packages\sklearn\utils\_response.py", line 214, in _get_response_values
    y_pred = prediction_method(X)
  File "E:\robo-data-scientist\venv\lib\site-packages\sklearn\neighbors\_classification.py", line 274, in predict
    neigh_ind = self.kneighbors(X, return_distance=False)
  File "E:\robo-data-scientist\venv\lib\site-packages\sklearn\neighbors\_base.py", line 854, in kneighbors
    raise ValueError(
ValueError: Expected n_neighbors <= n_samples_fit, but n_neighbors = 5, n_samples_fit = 4, n_samples = 4
"""

The above exception was the direct cause of the following exception:

Traceback (most recent call last):
  File "E:\robo-data-scientist\utils\model_trainer.py", line 192, in train_models
    grid_search_model.fit(X_train, y_train)
  File "E:\robo-data-scientist\venv\lib\site-packages\sklearn\base.py", line 1363, in wrapper
    return fit_method(estimator, *args, **kwargs)
  File "E:\robo-data-scientist\venv\lib\site-packages\sklearn\model_selection\_search.py", line 1051, in fit
    self._run_search(evaluate_candidates)
  File "E:\robo-data-scientist\venv\lib\site-packages\sklearn\model_selection\_search.py", line 1605, in _run_search
    evaluate_candidates(ParameterGrid(self.param_grid))
  File "E:\robo-data-scientist\venv\lib\site-packages\sklearn\model_selection\_search.py", line 997, in evaluate_candidates
    out = parallel(
  File "E:\robo-data-scientist\venv\lib\site-packages\sklearn\utils\parallel.py", line 82, in __call__
    return super().__call__(iterable_with_config_and_warning_filters)
  File "E:\robo-data-scientist\venv\lib\site-packages\joblib\parallel.py", line 2072, in __call__
    return output if self.return_generator else list(output)
  File "E:\robo-data-scientist\venv\lib\site-packages\joblib\parallel.py", line 1682, in _get_outputs
    yield from self._retrieve()
  File "E:\robo-data-scientist\venv\lib\site-packages\joblib\parallel.py", line 1784, in _retrieve
    self._raise_error_fast()
  File "E:\robo-data-scientist\venv\lib\site-packages\joblib\parallel.py", line 1859, in _raise_error_fast
    error_job.get_result(self.timeout)
  File "E:\robo-data-scientist\venv\lib\site-packages\joblib\parallel.py", line 758, in get_result
    return self._return_or_raise()
  File "E:\robo-data-scientist\venv\lib\site-packages\joblib\parallel.py", line 773, in _return_or_raise
    raise self._result
ValueError: Expected n_neighbors <= n_samples_fit, but n_neighbors = 5, n_samples_fit = 4, n_samples = 4
2025-06-16 15:10:23,978 | INFO |   Training NaiveBayes...
2025-06-16 15:10:23,995 | INFO |   NaiveBayes - Primary Metric (Accuracy): 0.0000
2025-06-16 15:10:23,995 | INFO |   Training SVM...
2025-06-16 15:10:29,073 | INFO |   SVM - Primary Metric (Accuracy): 0.0000
2025-06-16 15:10:29,073 | INFO |   Training GradientBoosting...
2025-06-16 15:10:33,312 | INFO |   GradientBoosting - Primary Metric (Accuracy): 0.0000
2025-06-16 15:10:33,312 | INFO |   Training XGBoost...
2025-06-16 15:10:36,369 | ERROR |   Skipping XGBoost due to error: Invalid classes inferred from unique values of `y`.  Expected: [0 1 2], got [ 7000.  9700. 22000.]
joblib.externals.loky.process_executor._RemoteTraceback: 
"""
Traceback (most recent call last):
  File "E:\robo-data-scientist\venv\lib\site-packages\joblib\externals\loky\process_executor.py", line 490, in _process_worker
    r = call_item()
  File "E:\robo-data-scientist\venv\lib\site-packages\joblib\externals\loky\process_executor.py", line 291, in __call__
    return self.fn(*self.args, **self.kwargs)
  File "E:\robo-data-scientist\venv\lib\site-packages\joblib\parallel.py", line 607, in __call__
    return [func(*args, **kwargs) for func, args, kwargs in self.items]
  File "E:\robo-data-scientist\venv\lib\site-packages\joblib\parallel.py", line 607, in <listcomp>
    return [func(*args, **kwargs) for func, args, kwargs in self.items]
  File "E:\robo-data-scientist\venv\lib\site-packages\sklearn\utils\parallel.py", line 147, in __call__
    return self.function(*args, **kwargs)
  File "E:\robo-data-scientist\venv\lib\site-packages\sklearn\model_selection\_validation.py", line 859, in _fit_and_score
    estimator.fit(X_train, y_train, **fit_params)
  File "E:\robo-data-scientist\venv\lib\site-packages\xgboost\core.py", line 729, in inner_f
    return func(**kwargs)
  File "E:\robo-data-scientist\venv\lib\site-packages\xgboost\sklearn.py", line 1640, in fit
    raise ValueError(
ValueError: Invalid classes inferred from unique values of `y`.  Expected: [0 1 2], got [ 7000.  9700. 22000.]
"""

The above exception was the direct cause of the following exception:

Traceback (most recent call last):
  File "E:\robo-data-scientist\utils\model_trainer.py", line 192, in train_models
    grid_search_model.fit(X_train, y_train)
  File "E:\robo-data-scientist\venv\lib\site-packages\sklearn\base.py", line 1363, in wrapper
    return fit_method(estimator, *args, **kwargs)
  File "E:\robo-data-scientist\venv\lib\site-packages\sklearn\model_selection\_search.py", line 1051, in fit
    self._run_search(evaluate_candidates)
  File "E:\robo-data-scientist\venv\lib\site-packages\sklearn\model_selection\_search.py", line 1605, in _run_search
    evaluate_candidates(ParameterGrid(self.param_grid))
  File "E:\robo-data-scientist\venv\lib\site-packages\sklearn\model_selection\_search.py", line 997, in evaluate_candidates
    out = parallel(
  File "E:\robo-data-scientist\venv\lib\site-packages\sklearn\utils\parallel.py", line 82, in __call__
    return super().__call__(iterable_with_config_and_warning_filters)
  File "E:\robo-data-scientist\venv\lib\site-packages\joblib\parallel.py", line 2072, in __call__
    return output if self.return_generator else list(output)
  File "E:\robo-data-scientist\venv\lib\site-packages\joblib\parallel.py", line 1682, in _get_outputs
    yield from self._retrieve()
  File "E:\robo-data-scientist\venv\lib\site-packages\joblib\parallel.py", line 1784, in _retrieve
    self._raise_error_fast()
  File "E:\robo-data-scientist\venv\lib\site-packages\joblib\parallel.py", line 1859, in _raise_error_fast
    error_job.get_result(self.timeout)
  File "E:\robo-data-scientist\venv\lib\site-packages\joblib\parallel.py", line 758, in get_result
    return self._return_or_raise()
  File "E:\robo-data-scientist\venv\lib\site-packages\joblib\parallel.py", line 773, in _return_or_raise
    raise self._result
ValueError: Invalid classes inferred from unique values of `y`.  Expected: [0 1 2], got [ 7000.  9700. 22000.]
2025-06-16 15:10:36,371 | INFO |   Training LightGBM...
2025-06-16 15:10:41,107 | INFO |   LightGBM - Primary Metric (Accuracy): 0.0000
2025-06-16 15:10:41,108 | INFO |   Training CatBoost...
2025-06-16 15:10:47,797 | INFO |   CatBoost - Primary Metric (Accuracy): 0.0000
2025-06-16 15:10:47,797 | INFO | 
ü§ù Building Ensemble Models (Classification)...
2025-06-16 15:10:47,797 | INFO |   Not enough base models available for VotingEnsemble or some failed.
2025-06-16 15:10:47,798 | INFO |   Not enough base models available for StackingEnsemble or some failed.
2025-06-16 15:10:47,798 | INFO | 
‚úÖ All models trained.
